<?xml version="1.0" ?>
<!-- Revolute-Revolute Manipulator -->
<robot name="rrbot" xmlns:xacro="http://www.ros.org/wiki/xacro">
  <!-- Import Rviz colors -->
  <material name="black">
    <color rgba="0.0 0.0 0.0 1.0"/>
  </material>
  <material name="blue">
    <color rgba="0.0 0.0 0.8 1.0"/>
  </material>
  <material name="green">
    <color rgba="0.0 0.8 0.0 1.0"/>
  </material>
  <material name="grey">
    <color rgba="0.2 0.2 0.2 1.0"/>
  </material>
  <material name="orange">
    <color rgba="1.0 0.423529411765 0.0392156862745 1.0"/>
  </material>
  <material name="brown">
    <color rgba="0.870588235294 0.811764705882 0.764705882353 1.0"/>
  </material>
  <material name="red">
    <color rgba="0.8 0.0 0.0 1.0"/>
  </material>
  <material name="white">
    <color rgba="1.0 1.0 1.0 1.0"/>
  </material>
  <!-- Used for fixing robot to Gazebo 'base_link' -->
  <link name="world"/>
  <joint name="fixed" type="fixed">
    <parent link="world"/>
    <child link="link1"/>
  </joint>
  <!-- Base Link -->
  <link name="link1">
    <collision>
      <origin rpy="0 0 0" xyz="0 0 1.0"/>
      <geometry>
        <box size="0.1 0.1 2"/>
      </geometry>
    </collision>
    <visual>
      <origin rpy="0 0 0" xyz="0 0 1.0"/>
      <geometry>
        <box size="0.1 0.1 2"/>
      </geometry>
      <material name="orange"/>
    </visual>
    <inertial>
      <origin rpy="0 0 0" xyz="0 0 1.0"/>
      <mass value="1"/>
      <inertia ixx="1.0" ixy="0.0" ixz="0.0" iyy="1.0" iyz="0.0" izz="1.0"/>
    </inertial>
  </link>
  <joint name="joint1" type="continuous" kinematic="False">
    <parent link="link1"/>
    <child link="link2"/>
    <origin rpy="0 0 0" xyz="0 0.1 1.95"/>
    <axis xyz="0 1 0"/>
    <dynamics damping="0.7"/>
  </joint>
  <!-- Middle Link -->
  <link name="link2">
    <collision>
      <origin rpy="0 0 0" xyz="0 0 0.45"/>
      <geometry>
        <box size="0.1 0.1 1"/>
      </geometry>
    </collision>
    <visual>
      <origin rpy="0 0 0" xyz="0 0 0.45"/>
      <geometry>
        <box size="0.1 0.1 1"/>
      </geometry>
      <material name="black"/>
    </visual>
    <inertial>
      <origin rpy="0 0 0" xyz="0 0 0.45"/>
      <mass value="1"/>
      <inertia ixx="1.0" ixy="0.0" ixz="0.0" iyy="1.0" iyz="0.0" izz="1.0"/>
    </inertial>
  </link>
  <joint name="joint2" type="continuous" kinematic="False">
    <parent link="link2"/>
    <child link="link3"/>
    <origin rpy="0 0 0" xyz="0 0.1 0.9"/>
    <axis xyz="0 1 0"/>
    <dynamics damping="0.7"/>
  </joint>
  <!-- Top Link -->
  <link name="link3">
    <collision>
      <origin rpy="0 0 0" xyz="0 0 0.45"/>
      <geometry>
        <box size="0.1 0.1 1"/>
      </geometry>
    </collision>
    <visual>
      <origin rpy="0 0 0" xyz="0 0 0.45"/>
      <geometry>
        <box size="0.1 0.1 1"/>
      </geometry>
      <material name="orange"/>
    </visual>
    <inertial>
      <origin rpy="0 0 0" xyz="0 0 0.45"/>
      <mass value="1"/>
      <inertia ixx="1.0" ixy="0.0" ixz="0.0" iyy="1.0" iyz="0.0" izz="1.0"/>
    </inertial>
  </link>
  <joint name="camera_joint" type="fixed">
    <axis xyz="0 1 0"/>
    <origin rpy="0 0 0" xyz="0.05 0 0.9"/>
    <parent link="link3"/>
    <child link="camera_link"/>
  </joint>
  <!-- Camera -->
  <link name="camera_link">
    <collision>
      <origin rpy="0 0 0" xyz="0 0 0"/>
      <geometry>
        <box size="0.05 0.05 0.05"/>
      </geometry>
    </collision>
    <visual>
      <origin rpy="0 0 0" xyz="0 0 0"/>
      <geometry>
        <box size="0.05 0.05 0.05"/>
      </geometry>
      <material name="red"/>
    </visual>
    <inertial>
      <mass value="1e-5"/>
      <origin rpy="0 0 0" xyz="0 0 0"/>
      <inertia ixx="1e-6" ixy="0" ixz="0" iyy="1e-6" iyz="0" izz="1e-6"/>
    </inertial>
  </link>
</robot>