<?xml version="1.0"?>
<robot name="iDynTreeURDFModelExportModelName">
  <link name="root_link">
    <inertial>
      <mass value="42.30274274"/>
      <origin xyz="0.004737074447815108 0.02462056083886382 0.0156306565874307" rpy="0 -0 0"/>
      <inertia ixx="4.173478391249159" ixy="-0.005664785945156598" ixz="0.09972258886014448" iyy="3.9323090538864722" iyz="0.35204722777278596" izz="0.3471838194857171"/>
    </inertial>
    <visual>
      <origin xyz="0 0 0.313858" rpy="0 -0 -1.5707963267948966"/>
      <geometry>
        <mesh filename="package://iCub/meshes/simmechanics/sim_icub3_root_link_prt.stl" scale="0.001 0.001 0.001"/>
      </geometry>
    </visual>
    <visual>
      <origin xyz="0 0 0.31385800000000014" rpy="0 -0 -1.5707963267948966"/>
      <geometry>
        <mesh filename="package://iCub/meshes/simmechanics/sim_icub3_torso_1_prt.stl" scale="0.001 0.001 0.001"/>
      </geometry>
    </visual>
    <visual>
      <origin xyz="-4.85722573273506e-17 3.3306690738754696e-16 0.3138580000000002" rpy="0 -0 -1.5707963267948966"/>
      <geometry>
        <mesh filename="package://iCub/meshes/simmechanics/sim_icub3_l_hip_1_prt.stl" scale="0.001 0.001 0.001"/>
      </geometry>
    </visual>
    <visual>
      <origin xyz="-7.632783294297951e-17 2.498001805406602e-16 0.31385800000000036" rpy="0 -0 -1.5707963267948966"/>
      <geometry>
        <mesh filename="package://iCub/meshes/simmechanics/sim_icub3_l_hip_2_prt.stl" scale="0.001 0.001 0.001"/>
      </geometry>
    </visual>
    <visual>
      <origin xyz="-7.806255641895632e-17 2.636779683484747e-16 0.31385800000000036" rpy="0 -0 -1.5707963267948966"/>
      <geometry>
        <mesh filename="package://iCub/meshes/simmechanics/sim_icub3_l_hip_3_prt.stl" scale="0.001 0.001 0.001"/>
      </geometry>
    </visual>
    <visual>
      <origin xyz="-8.673617379884035e-17 1.8735013540549517e-16 0.3138580000000004" rpy="0 -0 -1.5707963267948966"/>
      <geometry>
        <mesh filename="package://iCub/meshes/simmechanics/sim_icub3_l_upper_leg_prt.stl" scale="0.001 0.001 0.001"/>
      </geometry>
    </visual>
    <visual>
      <origin xyz="-4.85722573273506e-17 1.249000902703301e-16 0.31385800000000047" rpy="0 -0 -1.5707963267948966"/>
      <geometry>
        <mesh filename="package://iCub/meshes/simmechanics/sim_icub3_l_lower_leg_prt.stl" scale="0.001 0.001 0.001"/>
      </geometry>
    </visual>
    <visual>
      <origin xyz="0 2.7755575615628914e-17 0.3138580000000003" rpy="0 -0 -1.5707963267948966"/>
      <geometry>
        <mesh filename="package://iCub/meshes/simmechanics/sim_icub3_l_ankle_1_prt.stl" scale="0.001 0.001 0.001"/>
      </geometry>
    </visual>
    <visual>
      <origin xyz="6.938893903907228e-18 -1.1823875212257917e-14 0.3138579999999994" rpy="0 -0 -1.5707963267948966"/>
      <geometry>
        <mesh filename="package://iCub/meshes/simmechanics/sim_icub3_l_ankle_2_prt.stl" scale="0.001 0.001 0.001"/>
      </geometry>
    </visual>
    <visual>
      <origin xyz="3.469446951953614e-18 -1.1823875212257917e-14 0.3138579999999994" rpy="0 -0 -1.5707963267948966"/>
      <geometry>
        <mesh filename="package://iCub/meshes/simmechanics/sim_icub3_l_foot_rear_prt.stl" scale="0.001 0.001 0.001"/>
      </geometry>
    </visual>
    <visual>
      <origin xyz="0 -1.1823875212257917e-14 0.3138579999999994" rpy="0 -0 -1.5707963267948966"/>
      <geometry>
        <mesh filename="package://iCub/meshes/simmechanics/sim_icub3_l_foot_front_prt.stl" scale="0.001 0.001 0.001"/>
      </geometry>
    </visual>
    <visual>
      <origin xyz="0 0 0.31385800000000014" rpy="0 -0 -1.5707963267948966"/>
      <geometry>
        <mesh filename="package://iCub/meshes/simmechanics/sim_icub3_torso_2_prt.stl" scale="0.001 0.001 0.001"/>
      </geometry>
    </visual>
    <visual>
      <origin xyz="0 0 0.31385800000000014" rpy="0 -0 -1.5707963267948966"/>
      <geometry>
        <mesh filename="package://iCub/meshes/simmechanics/sim_icub3_chest_prt.stl" scale="0.001 0.001 0.001"/>
      </geometry>
    </visual>
    <visual>
      <origin xyz="-2.356718986629147e-12 -2.7911700728466826e-13 0.3138580000033983" rpy="1.079369279232929e-10 -2.8921599571759945e-11 -1.570796326823819"/>
      <geometry>
        <mesh filename="package://iCub/meshes/simmechanics/sim_icub3_l_shoulder_1_prt.stl" scale="0.001 0.001 0.001"/>
      </geometry>
    </visual>
    <visual>
      <origin xyz="-1.1102230246251565e-16 2.0816681711721685e-17 0.3138580000000001" rpy="7.011934613740151e-17 -3.6613184433524344e-17 -1.570796326794897"/>
      <geometry>
        <mesh filename="package://iCub/meshes/simmechanics/sim_icub3_r_shoulder_1_prt.stl" scale="0.001 0.001 0.001"/>
      </geometry>
    </visual>
    <visual>
      <origin xyz="-1.209969624493823e-16 0 0.31385800000000014" rpy="0 -0 -1.5707963267948966"/>
      <geometry>
        <mesh filename="package://iCub/meshes/simmechanics/sim_icub3_neck_1_prt.stl" scale="0.001 0.001 0.001"/>
      </geometry>
    </visual>
    <visual>
      <origin xyz="-1.231653667943533e-16 0 0.3138580000000001" rpy="0 -0 -1.5707963267948966"/>
      <geometry>
        <mesh filename="package://iCub/meshes/simmechanics/sim_icub3_neck_2_prt.stl" scale="0.001 0.001 0.001"/>
      </geometry>
    </visual>
    <visual>
      <origin xyz="-7.632783294297951e-17 0 0.3138580000000001" rpy="0 -0 -1.5707963267948966"/>
      <geometry>
        <mesh filename="package://iCub/meshes/simmechanics/sim_icub3_neck_3_prt.stl" scale="0.001 0.001 0.001"/>
      </geometry>
    </visual>
    <visual>
      <origin xyz="-8.413408858487514e-17 0 0.31385799999999997" rpy="0 -0 -1.5707963267948966"/>
      <geometry>
        <mesh filename="package://iCub/meshes/simmechanics/sim_icub3_head_prt.stl" scale="0.001 0.001 0.001"/>
      </geometry>
    </visual>
    <visual>
      <origin xyz="-9.8879238130678e-17 -8.326672684688674e-17 0.31385800000000014" rpy="3.469446951953614e-17 -5.551115123125783e-17 -1.570796326794897"/>
      <geometry>
        <mesh filename="package://iCub/meshes/simmechanics/sim_icub3_r_shoulder_2_prt.stl" scale="0.001 0.001 0.001"/>
      </geometry>
    </visual>
    <visual>
      <origin xyz="-9.71445146547012e-17 -8.326672684688674e-17 0.3138580000000001" rpy="3.469446951953614e-17 -5.551115123125783e-17 -1.570796326794897"/>
      <geometry>
        <mesh filename="package://iCub/meshes/simmechanics/sim_icub3_r_shoulder_3_prt.stl" scale="0.001 0.001 0.001"/>
      </geometry>
    </visual>
    <visual>
      <origin xyz="-7.871785179594526e-8 -2.2233801577620227e-8 0.31385799574009654" rpy="3.469446951953614e-17 -5.551115123125783e-17 -1.570796326794897"/>
      <geometry>
        <mesh filename="package://iCub/meshes/simmechanics/sim_icub3_r_upperarm_prt.stl" scale="0.001 0.001 0.001"/>
      </geometry>
    </visual>
    <visual>
      <origin xyz="-7.871785187921199e-8 -2.2233801577620227e-8 0.31385799574009654" rpy="3.469446951953614e-17 -5.551115123125783e-17 -1.570796326794897"/>
      <geometry>
        <mesh filename="package://iCub/meshes/simmechanics/sim_icub3_r_elbow_1_prt.stl" scale="0.001 0.001 0.001"/>
      </geometry>
    </visual>
    <visual>
      <origin xyz="-7.871785182717028e-8 -2.2233801633131378e-8 0.31385799574009654" rpy="3.469446951953614e-17 -5.551115123125783e-17 -1.570796326794897"/>
      <geometry>
        <mesh filename="package://iCub/meshes/simmechanics/sim_icub3_r_forearm_prt.stl" scale="0.001 0.001 0.001"/>
      </geometry>
    </visual>
    <visual>
      <origin xyz="-7.871785179247581e-8 -2.223380143884235e-8 0.31385799574009654" rpy="3.469446951953614e-17 -5.551115123125783e-17 -1.570796326794897"/>
      <geometry>
        <mesh filename="package://iCub/meshes/simmechanics/sim_icub3_r_wrist_1_prt.stl" scale="0.001 0.001 0.001"/>
      </geometry>
    </visual>
    <visual>
      <origin xyz="-8.129860465388994e-8 -1.6479640818634067e-8 0.3138580745298016" rpy="-8.576709967234032e-9 -2.384360086107873e-9 -1.5707963274993695"/>
      <geometry>
        <mesh filename="package://iCub/meshes/simmechanics/sim_icub3_r_hand_prt.stl" scale="0.001 0.001 0.001"/>
      </geometry>
    </visual>
    <visual>
      <origin xyz="3.7736870538152e-9 -3.351684485508599e-10 0.31385800016899756" rpy="6.4220663301139966e-9 -1.72079016140525e-9 -1.570796301106635"/>
      <geometry>
        <mesh filename="package://iCub/meshes/simmechanics/sim_icub3_l_shoulder_2_prt.stl" scale="0.001 0.001 0.001"/>
      </geometry>
    </visual>
    <visual>
      <origin xyz="3.773687060754094e-9 -3.3516847630643554e-10 0.31385800016899756" rpy="6.4220663301139966e-9 -1.72079016140525e-9 -1.570796301106635"/>
      <geometry>
        <mesh filename="package://iCub/meshes/simmechanics/sim_icub3_l_shoulder_3_prt.stl" scale="0.001 0.001 0.001"/>
      </geometry>
    </visual>
    <visual>
      <origin xyz="-7.461215345214156e-8 2.1803285066290812e-8 0.31385799593054625" rpy="6.52876129547675e-9 -1.7482815629216164e-9 -1.5707963011555104"/>
      <geometry>
        <mesh filename="package://iCub/meshes/simmechanics/sim_icub3_l_upperarm_prt.stl" scale="0.001 0.001 0.001"/>
      </geometry>
    </visual>
    <visual>
      <origin xyz="-7.461504419881138e-8 2.1803463173819537e-8 0.3138579959303502" rpy="6.52752033675208e-9 -1.7468511498419659e-9 -1.5707963011754635"/>
      <geometry>
        <mesh filename="package://iCub/meshes/simmechanics/sim_icub3_l_elbow_1_prt.stl" scale="0.001 0.001 0.001"/>
      </geometry>
    </visual>
    <visual>
      <origin xyz="-7.460690610444631e-8 2.1803385652496843e-8 0.31385799592734426" rpy="6.4220663301139966e-9 -1.72079016140525e-9 -1.570796301106635"/>
      <geometry>
        <mesh filename="package://iCub/meshes/simmechanics/sim_icub3_l_forearm_prt.stl" scale="0.001 0.001 0.001"/>
      </geometry>
    </visual>
    <visual>
      <origin xyz="-7.466821254353828e-8 2.1820039747266762e-8 0.31385799593446123" rpy="6.848899301858947e-9 -1.8394521374837103e-9 -1.5707963011416943"/>
      <geometry>
        <mesh filename="package://iCub/meshes/simmechanics/sim_icub3_l_wrist_1_prt.stl" scale="0.001 0.001 0.001"/>
      </geometry>
    </visual>
    <visual>
      <origin xyz="-8.027322179887664e-8 1.6956109849530776e-8 0.31385807412179023" rpy="6.848900307998563e-9 -1.8394521461573277e-9 -1.5707963011416939"/>
      <geometry>
        <mesh filename="package://iCub/meshes/simmechanics/sim_icub3_l_hand_prt.stl" scale="0.001 0.001 0.001"/>
      </geometry>
    </visual>
    <collision>
      <origin xyz="0 0 0.313858" rpy="0 -0 -1.5707963267948966"/>
      <geometry>
        <mesh filename="package://iCub/meshes/simmechanics/sim_icub3_root_link_prt.stl" scale="0.001 0.001 0.001"/>
      </geometry>
    </collision>
    <collision>
      <origin xyz="0 0 0.31385800000000014" rpy="0 -0 -1.5707963267948966"/>
      <geometry>
        <mesh filename="package://iCub/meshes/simmechanics/sim_icub3_torso_1_prt.stl" scale="0.001 0.001 0.001"/>
      </geometry>
    </collision>
    <collision>
      <origin xyz="-4.85722573273506e-17 3.3306690738754696e-16 0.3138580000000002" rpy="0 -0 -1.5707963267948966"/>
      <geometry>
        <mesh filename="package://iCub/meshes/simmechanics/sim_icub3_l_hip_1_prt.stl" scale="0.001 0.001 0.001"/>
      </geometry>
    </collision>
    <collision>
      <origin xyz="-7.632783294297951e-17 2.498001805406602e-16 0.31385800000000036" rpy="0 -0 -1.5707963267948966"/>
      <geometry>
        <mesh filename="package://iCub/meshes/simmechanics/sim_icub3_l_hip_2_prt.stl" scale="0.001 0.001 0.001"/>
      </geometry>
    </collision>
    <collision>
      <origin xyz="-7.806255641895632e-17 2.636779683484747e-16 0.31385800000000036" rpy="0 -0 -1.5707963267948966"/>
      <geometry>
        <mesh filename="package://iCub/meshes/simmechanics/sim_icub3_l_hip_3_prt.stl" scale="0.001 0.001 0.001"/>
      </geometry>
    </collision>
    <collision>
      <origin xyz="-8.673617379884035e-17 1.8735013540549517e-16 0.3138580000000004" rpy="0 -0 -1.5707963267948966"/>
      <geometry>
        <mesh filename="package://iCub/meshes/simmechanics/sim_icub3_l_upper_leg_prt.stl" scale="0.001 0.001 0.001"/>
      </geometry>
    </collision>
    <collision>
      <origin xyz="-4.85722573273506e-17 1.249000902703301e-16 0.31385800000000047" rpy="0 -0 -1.5707963267948966"/>
      <geometry>
        <mesh filename="package://iCub/meshes/simmechanics/sim_icub3_l_lower_leg_prt.stl" scale="0.001 0.001 0.001"/>
      </geometry>
    </collision>
    <collision>
      <origin xyz="0 2.7755575615628914e-17 0.3138580000000003" rpy="0 -0 -1.5707963267948966"/>
      <geometry>
        <mesh filename="package://iCub/meshes/simmechanics/sim_icub3_l_ankle_1_prt.stl" scale="0.001 0.001 0.001"/>
      </geometry>
    </collision>
    <collision>
      <origin xyz="6.938893903907228e-18 -1.1823875212257917e-14 0.3138579999999994" rpy="0 -0 -1.5707963267948966"/>
      <geometry>
        <mesh filename="package://iCub/meshes/simmechanics/sim_icub3_l_ankle_2_prt.stl" scale="0.001 0.001 0.001"/>
      </geometry>
    </collision>
    <collision>
      <origin xyz="3.469446951953614e-18 -1.1823875212257917e-14 0.3138579999999994" rpy="0 -0 -1.5707963267948966"/>
      <geometry>
        <mesh filename="package://iCub/meshes/simmechanics/sim_icub3_l_foot_rear_prt.stl" scale="0.001 0.001 0.001"/>
      </geometry>
    </collision>
    <collision>
      <origin xyz="0 -1.1823875212257917e-14 0.3138579999999994" rpy="0 -0 -1.5707963267948966"/>
      <geometry>
        <mesh filename="package://iCub/meshes/simmechanics/sim_icub3_l_foot_front_prt.stl" scale="0.001 0.001 0.001"/>
      </geometry>
    </collision>
    <collision>
      <origin xyz="0 0 0.31385800000000014" rpy="0 -0 -1.5707963267948966"/>
      <geometry>
        <mesh filename="package://iCub/meshes/simmechanics/sim_icub3_torso_2_prt.stl" scale="0.001 0.001 0.001"/>
      </geometry>
    </collision>
    <collision>
      <origin xyz="0 0 0.31385800000000014" rpy="0 -0 -1.5707963267948966"/>
      <geometry>
        <mesh filename="package://iCub/meshes/simmechanics/sim_icub3_chest_prt.stl" scale="0.001 0.001 0.001"/>
      </geometry>
    </collision>
    <collision>
      <origin xyz="-2.356718986629147e-12 -2.7911700728466826e-13 0.3138580000033983" rpy="1.079369279232929e-10 -2.8921599571759945e-11 -1.570796326823819"/>
      <geometry>
        <mesh filename="package://iCub/meshes/simmechanics/sim_icub3_l_shoulder_1_prt.stl" scale="0.001 0.001 0.001"/>
      </geometry>
    </collision>
    <collision>
      <origin xyz="-1.1102230246251565e-16 2.0816681711721685e-17 0.3138580000000001" rpy="7.011934613740151e-17 -3.6613184433524344e-17 -1.570796326794897"/>
      <geometry>
        <mesh filename="package://iCub/meshes/simmechanics/sim_icub3_r_shoulder_1_prt.stl" scale="0.001 0.001 0.001"/>
      </geometry>
    </collision>
    <collision>
      <origin xyz="-1.209969624493823e-16 0 0.31385800000000014" rpy="0 -0 -1.5707963267948966"/>
      <geometry>
        <mesh filename="package://iCub/meshes/simmechanics/sim_icub3_neck_1_prt.stl" scale="0.001 0.001 0.001"/>
      </geometry>
    </collision>
    <collision>
      <origin xyz="-1.231653667943533e-16 0 0.3138580000000001" rpy="0 -0 -1.5707963267948966"/>
      <geometry>
        <mesh filename="package://iCub/meshes/simmechanics/sim_icub3_neck_2_prt.stl" scale="0.001 0.001 0.001"/>
      </geometry>
    </collision>
    <collision>
      <origin xyz="-7.632783294297951e-17 0 0.3138580000000001" rpy="0 -0 -1.5707963267948966"/>
      <geometry>
        <mesh filename="package://iCub/meshes/simmechanics/sim_icub3_neck_3_prt.stl" scale="0.001 0.001 0.001"/>
      </geometry>
    </collision>
    <collision>
      <origin xyz="-8.413408858487514e-17 0 0.31385799999999997" rpy="0 -0 -1.5707963267948966"/>
      <geometry>
        <mesh filename="package://iCub/meshes/simmechanics/sim_icub3_head_prt.stl" scale="0.001 0.001 0.001"/>
      </geometry>
    </collision>
    <collision>
      <origin xyz="-9.8879238130678e-17 -8.326672684688674e-17 0.31385800000000014" rpy="3.469446951953614e-17 -5.551115123125783e-17 -1.570796326794897"/>
      <geometry>
        <mesh filename="package://iCub/meshes/simmechanics/sim_icub3_r_shoulder_2_prt.stl" scale="0.001 0.001 0.001"/>
      </geometry>
    </collision>
    <collision>
      <origin xyz="-9.71445146547012e-17 -8.326672684688674e-17 0.3138580000000001" rpy="3.469446951953614e-17 -5.551115123125783e-17 -1.570796326794897"/>
      <geometry>
        <mesh filename="package://iCub/meshes/simmechanics/sim_icub3_r_shoulder_3_prt.stl" scale="0.001 0.001 0.001"/>
      </geometry>
    </collision>
    <collision>
      <origin xyz="-7.871785179594526e-8 -2.2233801577620227e-8 0.31385799574009654" rpy="3.469446951953614e-17 -5.551115123125783e-17 -1.570796326794897"/>
      <geometry>
        <mesh filename="package://iCub/meshes/simmechanics/sim_icub3_r_upperarm_prt.stl" scale="0.001 0.001 0.001"/>
      </geometry>
    </collision>
    <collision>
      <origin xyz="-7.871785187921199e-8 -2.2233801577620227e-8 0.31385799574009654" rpy="3.469446951953614e-17 -5.551115123125783e-17 -1.570796326794897"/>
      <geometry>
        <mesh filename="package://iCub/meshes/simmechanics/sim_icub3_r_elbow_1_prt.stl" scale="0.001 0.001 0.001"/>
      </geometry>
    </collision>
    <collision>
      <origin xyz="-7.871785182717028e-8 -2.2233801633131378e-8 0.31385799574009654" rpy="3.469446951953614e-17 -5.551115123125783e-17 -1.570796326794897"/>
      <geometry>
        <mesh filename="package://iCub/meshes/simmechanics/sim_icub3_r_forearm_prt.stl" scale="0.001 0.001 0.001"/>
      </geometry>
    </collision>
    <collision>
      <origin xyz="-7.871785179247581e-8 -2.223380143884235e-8 0.31385799574009654" rpy="3.469446951953614e-17 -5.551115123125783e-17 -1.570796326794897"/>
      <geometry>
        <mesh filename="package://iCub/meshes/simmechanics/sim_icub3_r_wrist_1_prt.stl" scale="0.001 0.001 0.001"/>
      </geometry>
    </collision>
    <collision>
      <origin xyz="-8.129860465388994e-8 -1.6479640818634067e-8 0.3138580745298016" rpy="-8.576709967234032e-9 -2.384360086107873e-9 -1.5707963274993695"/>
      <geometry>
        <mesh filename="package://iCub/meshes/simmechanics/sim_icub3_r_hand_prt.stl" scale="0.001 0.001 0.001"/>
      </geometry>
    </collision>
    <collision>
      <origin xyz="3.7736870538152e-9 -3.351684485508599e-10 0.31385800016899756" rpy="6.4220663301139966e-9 -1.72079016140525e-9 -1.570796301106635"/>
      <geometry>
        <mesh filename="package://iCub/meshes/simmechanics/sim_icub3_l_shoulder_2_prt.stl" scale="0.001 0.001 0.001"/>
      </geometry>
    </collision>
    <collision>
      <origin xyz="3.773687060754094e-9 -3.3516847630643554e-10 0.31385800016899756" rpy="6.4220663301139966e-9 -1.72079016140525e-9 -1.570796301106635"/>
      <geometry>
        <mesh filename="package://iCub/meshes/simmechanics/sim_icub3_l_shoulder_3_prt.stl" scale="0.001 0.001 0.001"/>
      </geometry>
    </collision>
    <collision>
      <origin xyz="-7.461215345214156e-8 2.1803285066290812e-8 0.31385799593054625" rpy="6.52876129547675e-9 -1.7482815629216164e-9 -1.5707963011555104"/>
      <geometry>
        <mesh filename="package://iCub/meshes/simmechanics/sim_icub3_l_upperarm_prt.stl" scale="0.001 0.001 0.001"/>
      </geometry>
    </collision>
    <collision>
      <origin xyz="-7.461504419881138e-8 2.1803463173819537e-8 0.3138579959303502" rpy="6.52752033675208e-9 -1.7468511498419659e-9 -1.5707963011754635"/>
      <geometry>
        <mesh filename="package://iCub/meshes/simmechanics/sim_icub3_l_elbow_1_prt.stl" scale="0.001 0.001 0.001"/>
      </geometry>
    </collision>
    <collision>
      <origin xyz="-7.460690610444631e-8 2.1803385652496843e-8 0.31385799592734426" rpy="6.4220663301139966e-9 -1.72079016140525e-9 -1.570796301106635"/>
      <geometry>
        <mesh filename="package://iCub/meshes/simmechanics/sim_icub3_l_forearm_prt.stl" scale="0.001 0.001 0.001"/>
      </geometry>
    </collision>
    <collision>
      <origin xyz="-7.466821254353828e-8 2.1820039747266762e-8 0.31385799593446123" rpy="6.848899301858947e-9 -1.8394521374837103e-9 -1.5707963011416943"/>
      <geometry>
        <mesh filename="package://iCub/meshes/simmechanics/sim_icub3_l_wrist_1_prt.stl" scale="0.001 0.001 0.001"/>
      </geometry>
    </collision>
    <collision>
      <origin xyz="-8.027322179887664e-8 1.6956109849530776e-8 0.31385807412179023" rpy="6.848900307998563e-9 -1.8394521461573277e-9 -1.5707963011416939"/>
      <geometry>
        <mesh filename="package://iCub/meshes/simmechanics/sim_icub3_l_hand_prt.stl" scale="0.001 0.001 0.001"/>
      </geometry>
    </collision>
  </link>
  <joint name="r_hip_pitch" type="revolute">
    <origin xyz="0.0216 -0.040549999999999996 0" rpy="0 -0 0"/>
    <axis xyz="0 -1 0"/>
    <parent link="root_link"/>
    <child link="r_hip_1"/>
  </joint>
  <link name="r_hip_1">
    <inertial>
      <mass value="2.48546"/>
      <origin xyz="-0.005357899999999999 -0.03359610000000001 -0.001346999999999987" rpy="0 -0 0"/>
      <inertia ixx="0.00230094" ixy="-3.9100879313042547e-5" ixz="2.810598501285251e-5" iyy="0.00285629" iyz="4.323311344416862e-5" izz="0.00246343"/>
    </inertial>
    <visual>
      <origin xyz="-0.021600000000000008 0.04054999999999993 0.313858" rpy="0 -0 -1.5707963267948966"/>
      <geometry>
        <mesh filename="package://iCub/meshes/simmechanics/sim_icub3_r_hip_1_prt.stl" scale="0.001 0.001 0.001"/>
      </geometry>
    </visual>
    <collision>
      <origin xyz="-0.021600000000000008 0.04054999999999993 0.313858" rpy="0 -0 -1.5707963267948966"/>
      <geometry>
        <mesh filename="package://iCub/meshes/simmechanics/sim_icub3_r_hip_1_prt.stl" scale="0.001 0.001 0.001"/>
      </geometry>
    </collision>
  </link>
  <joint name="r_hip_roll" type="revolute">
    <origin xyz="-0.0473 -0.03310000000000001 -0.009000000000000008" rpy="0 -0 0"/>
    <axis xyz="-1 0 0"/>
    <parent link="r_hip_1"/>
    <child link="r_hip_2"/>
  </joint>
  <link name="r_hip_2">
    <inertial>
      <mass value="4.17692"/>
      <origin xyz="0.019627786909971936 0.004614725261676077 -0.08903906509102397" rpy="0 -0 0"/>
      <inertia ixx="0.015609690179893422" ixy="-6.191825203406873e-4" ixz="0.005211286379560984" iyy="0.020417997609288106" iyz="3.8457345199612784e-4" izz="0.009652080350053483"/>
    </inertial>
    <visual>
      <origin xyz="0.025699999999999983 0.07364999999996628 0.32285800000000775" rpy="0 -0 -1.5707963267948966"/>
      <geometry>
        <mesh filename="package://iCub/meshes/simmechanics/sim_icub3_r_hip_2_prt.stl" scale="0.001 0.001 0.001"/>
      </geometry>
    </visual>
    <visual>
      <origin xyz="0.02569999999999998 0.07364999999996628 0.3228580000000077" rpy="0 -0 -1.5707963267948966"/>
      <geometry>
        <mesh filename="package://iCub/meshes/simmechanics/sim_icub3_r_hip_3_prt.stl" scale="0.001 0.001 0.001"/>
      </geometry>
    </visual>
    <collision>
      <origin xyz="0.025699999999999983 0.07364999999996628 0.32285800000000775" rpy="0 -0 -1.5707963267948966"/>
      <geometry>
        <mesh filename="package://iCub/meshes/simmechanics/sim_icub3_r_hip_2_prt.stl" scale="0.001 0.001 0.001"/>
      </geometry>
    </collision>
    <collision>
      <origin xyz="0.02569999999999998 0.07364999999996628 0.3228580000000077" rpy="0 -0 -1.5707963267948966"/>
      <geometry>
        <mesh filename="package://iCub/meshes/simmechanics/sim_icub3_r_hip_3_prt.stl" scale="0.001 0.001 0.001"/>
      </geometry>
    </collision>
  </link>
  <joint name="r_hip_yaw" type="revolute">
    <origin xyz="0.036699999999999997 0.015000000000000006 -0.16060000000000002" rpy="0 -0 0"/>
    <axis xyz="0 0 -1"/>
    <parent link="r_hip_2"/>
    <child link="r_upper_leg"/>
  </joint>
  <link name="r_upper_leg">
    <inertial>
      <mass value="2.24396"/>
      <origin xyz="0.0108785 -0.0010395000000000057 -0.08361700000000005" rpy="0 -0 0"/>
      <inertia ixx="0.004793840000000001" ixy="3.208266350807358e-5" ixz="4.429643744342077e-4" iyy="0.004762840000000001" iyz="-1.1628418121408619e-4" izz="0.0019452700000000002"/>
    </inertial>
    <visual>
      <origin xyz="-0.010999999999999998 0.05864999999996624 0.48345800000000777" rpy="0 -0 -1.5707963267948966"/>
      <geometry>
        <mesh filename="package://iCub/meshes/simmechanics/sim_icub3_r_upper_leg_prt.stl" scale="0.001 0.001 0.001"/>
      </geometry>
    </visual>
    <collision>
      <origin xyz="-0.010999999999999998 0.05864999999996624 0.48345800000000777" rpy="0 -0 -1.5707963267948966"/>
      <geometry>
        <mesh filename="package://iCub/meshes/simmechanics/sim_icub3_r_upper_leg_prt.stl" scale="0.001 0.001 0.001"/>
      </geometry>
    </collision>
  </link>
  <joint name="r_knee" type="revolute">
    <origin xyz="0.015000000000000003 -0.0249 -0.10619999999999996" rpy="0 -0 0"/>
    <axis xyz="0 -1 0"/>
    <parent link="r_upper_leg"/>
    <child link="r_lower_leg"/>
  </joint>
  <link name="r_lower_leg">
    <inertial>
      <mass value="4.59072"/>
      <origin xyz="-0.01980179 0.023727799999999993 -0.12894100000000008" rpy="0 -0 0"/>
      <inertia ixx="0.030975599999999992" ixy="-2.1016665674538997e-4" ixz="-1.5989465053380808e-4" iyy="0.033166299999999996" iyz="-1.230064685862186e-4" izz="0.005252510000000001"/>
    </inertial>
    <visual>
      <origin xyz="-0.026000000000000058 0.08354999999996623 0.5896580000000077" rpy="0 -0 -1.5707963267948966"/>
      <geometry>
        <mesh filename="package://iCub/meshes/simmechanics/sim_icub3_r_lower_leg_prt.stl" scale="0.001 0.001 0.001"/>
      </geometry>
    </visual>
    <collision>
      <origin xyz="-0.026000000000000058 0.08354999999996623 0.5896580000000077" rpy="0 -0 -1.5707963267948966"/>
      <geometry>
        <mesh filename="package://iCub/meshes/simmechanics/sim_icub3_r_lower_leg_prt.stl" scale="0.001 0.001 0.001"/>
      </geometry>
    </collision>
  </link>
  <joint name="r_ankle_pitch" type="revolute">
    <origin xyz="0 5.000000000000004e-4 -0.255989" rpy="0 -0 0"/>
    <axis xyz="0 1 0"/>
    <parent link="r_lower_leg"/>
    <child link="r_ankle_1"/>
  </joint>
  <link name="r_ankle_1">
    <inertial>
      <mass value="1.80595"/>
      <origin xyz="-0.0052558000000000014 0.0023015999999999874 -0.018286000000000024" rpy="0 -0 0"/>
      <inertia ixx="9.7845e-4" ixy="1.1193325094648421e-4" ixz="-1.0678991458219674e-4" iyy="0.0032910899999999996" iyz="2.3180543265495065e-4" izz="0.00298837"/>
    </inertial>
    <visual>
      <origin xyz="-0.02600000000000011 0.08304999999996568 0.8456470000000077" rpy="0 -0 -1.5707963267948966"/>
      <geometry>
        <mesh filename="package://iCub/meshes/simmechanics/sim_icub3_r_ankle_1_prt.stl" scale="0.001 0.001 0.001"/>
      </geometry>
    </visual>
    <collision>
      <origin xyz="-0.02600000000000011 0.08304999999996568 0.8456470000000077" rpy="0 -0 -1.5707963267948966"/>
      <geometry>
        <mesh filename="package://iCub/meshes/simmechanics/sim_icub3_r_ankle_1_prt.stl" scale="0.001 0.001 0.001"/>
      </geometry>
    </collision>
  </link>
  <joint name="r_ankle_roll" type="revolute">
    <origin xyz="-0.052750000000000005 0.018200000000000008 -0.03500000000000003" rpy="0 -0 0"/>
    <axis xyz="-1 0 0"/>
    <parent link="r_ankle_1"/>
    <child link="r_ankle_2"/>
  </joint>
  <link name="r_ankle_2">
    <inertial>
      <mass value="1.43897637"/>
      <origin xyz="0.051837328430864374 6.078574373252331e-5 -0.035585413760213395" rpy="0 -0 0"/>
      <inertia ixx="0.0024952611850815867" ixy="-2.0652633228576023e-6" ixz="0.0011190935209177393" iyy="0.008622766979840484" iyz="2.770101151131824e-6" izz="0.008857681808807291"/>
    </inertial>
    <visual>
      <origin xyz="0.026749999999999875 0.0648499999999391 0.8806470000000108" rpy="0 -0 -1.5707963267948966"/>
      <geometry>
        <mesh filename="package://iCub/meshes/simmechanics/sim_icub3_r_ankle_2_prt.stl" scale="0.001 0.001 0.001"/>
      </geometry>
    </visual>
    <visual>
      <origin xyz="0.02674999999999988 0.0648499999999391 0.8806470000000105" rpy="0 -0 -1.5707963267948966"/>
      <geometry>
        <mesh filename="package://iCub/meshes/simmechanics/sim_icub3_r_foot_rear_prt.stl" scale="0.001 0.001 0.001"/>
      </geometry>
    </visual>
    <visual>
      <origin xyz="0.0267499999999999 0.06484999999993908 0.8806470000000105" rpy="0 -0 -1.5707963267948966"/>
      <geometry>
        <mesh filename="package://iCub/meshes/simmechanics/sim_icub3_r_foot_front_prt.stl" scale="0.001 0.001 0.001"/>
      </geometry>
    </visual>
    <collision>
      <origin xyz="0.026749999999999875 0.0648499999999391 0.8806470000000108" rpy="0 -0 -1.5707963267948966"/>
      <geometry>
        <mesh filename="package://iCub/meshes/simmechanics/sim_icub3_r_ankle_2_prt.stl" scale="0.001 0.001 0.001"/>
      </geometry>
    </collision>
    <collision>
      <origin xyz="0.02674999999999988 0.0648499999999391 0.8806470000000105" rpy="0 -0 -1.5707963267948966"/>
      <geometry>
        <mesh filename="package://iCub/meshes/simmechanics/sim_icub3_r_foot_rear_prt.stl" scale="0.001 0.001 0.001"/>
      </geometry>
    </collision>
    <collision>
      <origin xyz="0.0267499999999999 0.06484999999993908 0.8806470000000105" rpy="0 -0 -1.5707963267948966"/>
      <geometry>
        <mesh filename="package://iCub/meshes/simmechanics/sim_icub3_r_foot_front_prt.stl" scale="0.001 0.001 0.001"/>
      </geometry>
    </collision>
  </link>
  <link name="base_link"/>
  <joint name="base_link_fixed_joint" type="fixed">
    <origin xyz="0 0 0" rpy="0 -0 0"/>
    <parent link="root_link"/>
    <child link="base_link"/>
  </joint>
  <link name="torso_1"/>
  <joint name="torso_1_fixed_joint" type="fixed">
    <origin xyz="0 0 0.0605" rpy="0 -0 0"/>
    <parent link="root_link"/>
    <child link="torso_1"/>
  </joint>
  <link name="l_hip_1"/>
  <joint name="l_hip_1_fixed_joint" type="fixed">
    <origin xyz="0.0216 0.04045000000000001 0" rpy="0 -0 0"/>
    <parent link="root_link"/>
    <child link="l_hip_1"/>
  </joint>
  <link name="l_hip_2"/>
  <joint name="l_hip_2_fixed_joint" type="fixed">
    <origin xyz="-0.02565 0.07355 -0.009000000000000008" rpy="0 -0 0"/>
    <parent link="root_link"/>
    <child link="l_hip_2"/>
  </joint>
  <link name="l_hip_3"/>
  <joint name="l_hip_3_fixed_joint" type="fixed">
    <origin xyz="0.011049999999999997 0.07355 -0.09869999999999995" rpy="0 -0 0"/>
    <parent link="root_link"/>
    <child link="l_hip_3"/>
  </joint>
  <link name="l_leg_ft_sensor"/>
  <joint name="l_leg_ft_sensor_fixed_joint" type="fixed">
    <origin xyz="0.011049999999999997 0.07355 -0.09869999999999995" rpy="0 -0 0"/>
    <parent link="root_link"/>
    <child link="l_leg_ft_sensor"/>
  </joint>
  <link name="l_upper_leg"/>
  <joint name="l_upper_leg_fixed_joint" type="fixed">
    <origin xyz="0.011049999999999997 0.05855 -0.16960000000000003" rpy="0 -0 0"/>
    <parent link="root_link"/>
    <child link="l_upper_leg"/>
  </joint>
  <link name="l_lower_leg"/>
  <joint name="l_lower_leg_fixed_joint" type="fixed">
    <origin xyz="0.026049999999999997 0.08345000000000001 -0.2758" rpy="0 -0 0"/>
    <parent link="root_link"/>
    <child link="l_lower_leg"/>
  </joint>
  <link name="l_ankle_1"/>
  <joint name="l_ankle_1_fixed_joint" type="fixed">
    <origin xyz="0.026049999999999997 0.08295000000000001 -0.5317890000000001" rpy="0 -0 0"/>
    <parent link="root_link"/>
    <child link="l_ankle_1"/>
  </joint>
  <link name="l_ankle_2"/>
  <joint name="l_ankle_2_fixed_joint" type="fixed">
    <origin xyz="-0.02670000000000001 0.06475 -0.5667890000000001" rpy="0 -0 0"/>
    <parent link="root_link"/>
    <child link="l_ankle_2"/>
  </joint>
  <link name="l_foot_rear"/>
  <joint name="l_foot_rear_fixed_joint" type="fixed">
    <origin xyz="-0.010700000000000008 0.06475 -0.6325890000000001" rpy="0 -0 0"/>
    <parent link="root_link"/>
    <child link="l_foot_rear"/>
  </joint>
  <link name="l_sole"/>
  <joint name="l_sole_fixed_joint" type="fixed">
    <origin xyz="0.048929999999999994 0.06475 -0.6325890000000001" rpy="0 -0 0"/>
    <parent link="root_link"/>
    <child link="l_sole"/>
  </joint>
  <link name="l_foot_rear_ft_sensor"/>
  <joint name="l_foot_rear_ft_sensor_fixed_joint" type="fixed">
    <origin xyz="-0.010700000000000008 0.06475 -0.6325890000000001" rpy="0 -0 0"/>
    <parent link="root_link"/>
    <child link="l_foot_rear_ft_sensor"/>
  </joint>
  <link name="l_foot_front"/>
  <joint name="l_foot_front_fixed_joint" type="fixed">
    <origin xyz="0.10854999999999998 0.06475 -0.6325890000000001" rpy="0 -0 0"/>
    <parent link="root_link"/>
    <child link="l_foot_front"/>
  </joint>
  <link name="l_foot_front_ft_sensor"/>
  <joint name="l_foot_front_ft_sensor_fixed_joint" type="fixed">
    <origin xyz="0.10854999999999998 0.06475 -0.6325890000000001" rpy="0 -0 0"/>
    <parent link="root_link"/>
    <child link="l_foot_front_ft_sensor"/>
  </joint>
  <link name="torso_2"/>
  <joint name="torso_2_fixed_joint" type="fixed">
    <origin xyz="0 0 0.133" rpy="0 -0 0"/>
    <parent link="root_link"/>
    <child link="torso_2"/>
  </joint>
  <link name="chest"/>
  <joint name="chest_fixed_joint" type="fixed">
    <origin xyz="0 0 0.19747000000000003" rpy="0 -0 0"/>
    <parent link="root_link"/>
    <child link="chest"/>
  </joint>
  <link name="l_shoulder_1"/>
  <joint name="l_shoulder_1_fixed_joint" type="fixed">
    <origin xyz="-0.020835100000000002 0.0397423 0.3026729" rpy="0.2532616237670649 -1.1982921379466467e-7 -0.26179930185680106"/>
    <parent link="root_link"/>
    <child link="l_shoulder_1"/>
  </joint>
  <link name="r_shoulder_1"/>
  <joint name="r_shoulder_1_fixed_joint" type="fixed">
    <origin xyz="-0.020835100000000002 -0.0397423 0.3026729" rpy="-0.25326164431680925 2.3014774394592079e-7 0.26179970938509745"/>
    <parent link="root_link"/>
    <child link="r_shoulder_1"/>
  </joint>
  <link name="neck_1"/>
  <joint name="neck_1_fixed_joint" type="fixed">
    <origin xyz="-0.00378849 0 0.3627695" rpy="0 -0 0"/>
    <parent link="root_link"/>
    <child link="neck_1"/>
  </joint>
  <link name="neck_2"/>
  <joint name="neck_2_fixed_joint" type="fixed">
    <origin xyz="0.0048615099999999994 0 0.4117695" rpy="0 -0 0"/>
    <parent link="root_link"/>
    <child link="neck_2"/>
  </joint>
  <link name="neck_3"/>
  <joint name="neck_3_fixed_joint" type="fixed">
    <origin xyz="0.0048615099999999994 0 0.42127000000000003" rpy="0 -0 0"/>
    <parent link="root_link"/>
    <child link="neck_3"/>
  </joint>
  <link name="head"/>
  <joint name="head_fixed_joint" type="fixed">
    <origin xyz="0.0048615099999999994 0 0.4904200000000001" rpy="0 -0 0"/>
    <parent link="root_link"/>
    <child link="head"/>
  </joint>
  <link name="r_shoulder_2"/>
  <joint name="r_shoulder_2_fixed_joint" type="fixed">
    <origin xyz="0.014310500000000032 -0.14197200000000007 0.33100070000000004" rpy="-0.07907934249382903 -0.0520316044795478 0.2752784843541201"/>
    <parent link="root_link"/>
    <child link="r_shoulder_2"/>
  </joint>
  <link name="r_shoulder_3"/>
  <joint name="r_shoulder_3_fixed_joint" type="fixed">
    <origin xyz="0.011602500000000036 -0.14719400000000007 0.27658740000000004" rpy="-0.07907934249382903 -0.0520316044795478 0.2752784843541201"/>
    <parent link="root_link"/>
    <child link="r_shoulder_3"/>
  </joint>
  <link name="r_arm_ft_sensor"/>
  <joint name="r_arm_ft_sensor_fixed_joint" type="fixed">
    <origin xyz="0.011602500000000036 -0.14719400000000007 0.27658740000000004" rpy="-0.07907934249382903 -0.0520316044795478 0.2752784843541201"/>
    <parent link="root_link"/>
    <child link="r_arm_ft_sensor"/>
  </joint>
  <link name="r_upper_arm"/>
  <joint name="r_upper_arm_fixed_joint" type="fixed">
    <origin xyz="0.013208121282148412 -0.14858702223380166 0.2541880957400964" rpy="-0.07907934249382903 -0.0520316044795478 0.2752784843541201"/>
    <parent link="root_link"/>
    <child link="r_upper_arm"/>
  </joint>
  <link name="r_elbow_1"/>
  <joint name="r_elbow_1_fixed_joint" type="fixed">
    <origin xyz="0.031246121282148414 -0.1520930222338017 0.13144299574009638" rpy="-0.07907934249382903 -0.0520316044795478 0.2752784843541201"/>
    <parent link="root_link"/>
    <child link="r_elbow_1"/>
  </joint>
  <link name="r_forearm"/>
  <joint name="r_forearm_fixed_joint" type="fixed">
    <origin xyz="0.021311021282148408 -0.16151002223380165 0.0757679957400964" rpy="-0.07907934249382903 -0.0520316044795478 0.2752784843541201"/>
    <parent link="root_link"/>
    <child link="r_forearm"/>
  </joint>
  <link name="r_wrist_1"/>
  <joint name="r_wrist_1_fixed_joint" type="fixed">
    <origin xyz="0.045183921282148404 -0.16567102223380167 -0.030245004259903563" rpy="-0.07907934249382903 -0.0520316044795478 0.2752784843541201"/>
    <parent link="root_link"/>
    <child link="r_wrist_1"/>
  </joint>
  <link name="r_hand"/>
  <joint name="r_hand_fixed_joint" type="fixed">
    <origin xyz="0.027649815623035374 -0.16337301732292386 -0.031644925317804405" rpy="-0.07907934249382903 -0.0520316044795478 0.2752784843541201"/>
    <parent link="root_link"/>
    <child link="r_hand"/>
  </joint>
  <link name="l_shoulder_2"/>
  <joint name="l_shoulder_2_fixed_joint" type="fixed">
    <origin xyz="0.011907900000000013 0.14265000000000003 0.3308707" rpy="0.0790794230156212 -0.052031613930206826 -0.27527862099575323"/>
    <parent link="root_link"/>
    <child link="l_shoulder_2"/>
  </joint>
  <link name="l_shoulder_3"/>
  <joint name="l_shoulder_3_fixed_joint" type="fixed">
    <origin xyz="0.01160250023188351 0.14719399989874468 0.2765873999902195" rpy="0.0790794230156212 -0.052031613930206826 -0.27527862099575323"/>
    <parent link="root_link"/>
    <child link="l_shoulder_3"/>
  </joint>
  <link name="l_arm_ft_sensor"/>
  <joint name="l_arm_ft_sensor_fixed_joint" type="fixed">
    <origin xyz="0.01160250023188351 0.14719399989874468 0.2765873999902195" rpy="0.0790794230156212 -0.052031613930206826 -0.27527862099575323"/>
    <parent link="root_link"/>
    <child link="l_arm_ft_sensor"/>
  </joint>
  <link name="l_upper_arm"/>
  <joint name="l_upper_arm_fixed_joint" type="fixed">
    <origin xyz="0.013208121959356507 0.14858702204000246 0.2541880957564809" rpy="0.0790794230156212 -0.052031613930206826 -0.27527862099575323"/>
    <parent link="root_link"/>
    <child link="l_upper_arm"/>
  </joint>
  <link name="l_elbow_1"/>
  <joint name="l_elbow_1_fixed_joint" type="fixed">
    <origin xyz="0.031246122657570638 0.15209302229214877 0.13144299586628905" rpy="0.0790794230156212 -0.052031613930206826 -0.27527862099575323"/>
    <parent link="root_link"/>
    <child link="l_elbow_1"/>
  </joint>
  <link name="l_forearm"/>
  <joint name="l_forearm_fixed_joint" type="fixed">
    <origin xyz="0.021311022773212826 0.16151002194112832 0.07576799578628049" rpy="0.0790794230156212 -0.052031613930206826 -0.27527862099575323"/>
    <parent link="root_link"/>
    <child link="l_forearm"/>
  </joint>
  <link name="l_wrist_1"/>
  <joint name="l_wrist_1_fixed_joint" type="fixed">
    <origin xyz="0.04547212334915017 0.1655890223793864 -0.030229004065574397" rpy="0.0790794230156212 -0.052031613930206826 -0.27527862099575323"/>
    <parent link="root_link"/>
    <child link="l_wrist_1"/>
  </joint>
  <link name="l_hand"/>
  <joint name="l_hand_fixed_joint" type="fixed">
    <origin xyz="0.027938017812163745 0.16329101706262705 -0.031628925986897" rpy="0.0790794230156212 -0.052031613930206826 -0.27527862099575323"/>
    <parent link="root_link"/>
    <child link="l_hand"/>
  </joint>
  <link name="r_hip_3"/>
  <joint name="r_hip_3_fixed_joint" type="fixed">
    <origin xyz="0.036699999999999997 0 -0.08969999999999995" rpy="0 -0 0"/>
    <parent link="r_hip_2"/>
    <child link="r_hip_3"/>
  </joint>
  <link name="r_leg_ft_sensor"/>
  <joint name="r_leg_ft_sensor_fixed_joint" type="fixed">
    <origin xyz="0.036699999999999997 0 -0.08969999999999995" rpy="0 -0 0"/>
    <parent link="r_hip_2"/>
    <child link="r_leg_ft_sensor"/>
  </joint>
  <link name="r_foot_rear"/>
  <joint name="r_foot_rear_fixed_joint" type="fixed">
    <origin xyz="0.016 0 -0.06579999999999997" rpy="0 -0 0"/>
    <parent link="r_ankle_2"/>
    <child link="r_foot_rear"/>
  </joint>
  <link name="r_sole"/>
  <joint name="r_sole_fixed_joint" type="fixed">
    <origin xyz="0.07563 0 -0.06579999999999997" rpy="0 -0 0"/>
    <parent link="r_ankle_2"/>
    <child link="r_sole"/>
  </joint>
  <link name="r_foot_rear_ft_sensor"/>
  <joint name="r_foot_rear_ft_sensor_fixed_joint" type="fixed">
    <origin xyz="0.016 0 -0.06579999999999997" rpy="0 -0 0"/>
    <parent link="r_ankle_2"/>
    <child link="r_foot_rear_ft_sensor"/>
  </joint>
  <link name="r_foot_front"/>
  <joint name="r_foot_front_fixed_joint" type="fixed">
    <origin xyz="0.13525 0 -0.06579999999999997" rpy="0 -0 0"/>
    <parent link="r_ankle_2"/>
    <child link="r_foot_front"/>
  </joint>
  <link name="r_foot_front_ft_sensor"/>
  <joint name="r_foot_front_ft_sensor_fixed_joint" type="fixed">
    <origin xyz="0.13525 0 -0.06579999999999997" rpy="0 -0 0"/>
    <parent link="r_ankle_2"/>
    <child link="r_foot_front_ft_sensor"/>
  </joint>
</robot>
